2024-04-18 17:42:49 - ERROR: [Errno 2] No such file or directory: 'models/model_description.csv' - ERROR from __init__ in file Classifier.py
2024-04-18 17:46:14 - ERROR: [Errno 2] No such file or directory: 'C:\\Users\\ritik\\Documents\\DS5010-Final-Project/models/model_description.csv' - ERROR from __init__ in file Classifier.py
2024-04-18 17:47:56 - ERROR: [Errno 2] No such file or directory: 'C:\\Users\\ritik\\Documents\\DS5010-Final-Project\\models/model_description.csv' - ERROR from __init__ in file Classifier.py
2024-04-18 17:48:30 - ERROR: [Errno 2] No such file or directory: 'C:\\models\\model_description.csv' - ERROR from __init__ in file Classifier.py
2024-04-18 17:52:21 - ERROR: [Errno 2] No such file or directory: 'C:\\Users\\ritik\\Documents\\DS5010-Final-Project\\models\\model_description.csv' - ERROR from __init__ in file Classifier.py
2024-04-19 14:44:39 - ERROR: Exception encountered when calling layer 'embeddings' (type TFBertEmbeddings).

{{function_node __wrapped__ResourceGather_device_/job:localhost/replica:0/task:0/device:CPU:0}} indices[0,512] = 512 is not in [0, 512) [Op:ResourceGather] name: 

Call arguments received by layer 'embeddings' (type TFBertEmbeddings):
  • input_ids=tf.Tensor(shape=(1, 580), dtype=int32)
  • position_ids=None
  • token_type_ids=tf.Tensor(shape=(1, 580), dtype=int32)
  • inputs_embeds=None
  • past_key_values_length=0
  • training=False - ERROR from get_bert_embeddings in file TextEmbedding.py
2024-04-19 14:50:09 - ERROR: Exception encountered when calling layer 'embeddings' (type TFBertEmbeddings).

{{function_node __wrapped__ResourceGather_device_/job:localhost/replica:0/task:0/device:CPU:0}} indices[0,512] = 512 is not in [0, 512) [Op:ResourceGather] name: 

Call arguments received by layer 'embeddings' (type TFBertEmbeddings):
  • input_ids=tf.Tensor(shape=(1, 580), dtype=int32)
  • position_ids=None
  • token_type_ids=tf.Tensor(shape=(1, 580), dtype=int32)
  • inputs_embeds=None
  • past_key_values_length=0
  • training=False - ERROR from get_bert_embeddings in file TextEmbedding.py
2024-04-19 14:51:34 - ERROR: Exception encountered when calling layer 'embeddings' (type TFBertEmbeddings).

{{function_node __wrapped__ResourceGather_device_/job:localhost/replica:0/task:0/device:CPU:0}} indices[0,512] = 512 is not in [0, 512) [Op:ResourceGather] name: 

Call arguments received by layer 'embeddings' (type TFBertEmbeddings):
  • input_ids=tf.Tensor(shape=(1, 580), dtype=int32)
  • position_ids=None
  • token_type_ids=tf.Tensor(shape=(1, 580), dtype=int32)
  • inputs_embeds=None
  • past_key_values_length=0
  • training=False - ERROR from get_bert_embeddings in file TextEmbedding.py
2024-04-20 12:49:32 - ERROR: name 'os' is not defined - ERROR from __init__ in file Classifier.py
